2024-06-18 11:55:16,899 INFO    StreamThr :22507 [internal.py:wandb_internal():85] W&B internal server running at pid: 22507, started at: 2024-06-18 11:55:16.899433
2024-06-18 11:55:16,901 DEBUG   HandlerThread:22507 [handler.py:handle_request():158] handle_request: status
2024-06-18 11:55:16,908 INFO    WriterThread:22507 [datastore.py:open_for_write():87] open: /home/harsh/Downloads/PROJECTS/road_detection_unet/wandb/run-20240618_115516-3nfitrn2/run-3nfitrn2.wandb
2024-06-18 11:55:16,908 DEBUG   SenderThread:22507 [sender.py:send():379] send: header
2024-06-18 11:55:16,939 DEBUG   SenderThread:22507 [sender.py:send():379] send: run
2024-06-18 11:55:17,491 ERROR   SenderThread:22507 [internal_api.py:execute():344] 404 response executing GraphQL.
2024-06-18 11:55:17,491 ERROR   SenderThread:22507 [internal_api.py:execute():345] {"errors":[{"message":"entity your_entity not found during upsertBucket","path":["upsertBucket"]}],"data":{"upsertBucket":null}}
2024-06-18 11:55:17,491 ERROR   SenderThread:22507 [sender.py:send_run():1009] It appears that you do not have permission to access the requested resource. Please reach out to the project owner to grant you access. If you have the correct permissions, verify that there are no issues with your networking setup.(Error 404: Not Found)
Traceback (most recent call last):
  File "/home/harsh/anaconda3/envs/unet_env/lib/python3.8/site-packages/wandb/sdk/lib/retry.py", line 131, in __call__
    result = self._call_fn(*args, **kwargs)
  File "/home/harsh/anaconda3/envs/unet_env/lib/python3.8/site-packages/wandb/sdk/internal/internal_api.py", line 340, in execute
    return self.client.execute(*args, **kwargs)  # type: ignore
  File "/home/harsh/anaconda3/envs/unet_env/lib/python3.8/site-packages/wandb/vendor/gql-0.2.0/wandb_gql/client.py", line 52, in execute
    result = self._get_result(document, *args, **kwargs)
  File "/home/harsh/anaconda3/envs/unet_env/lib/python3.8/site-packages/wandb/vendor/gql-0.2.0/wandb_gql/client.py", line 60, in _get_result
    return self.transport.execute(document, *args, **kwargs)
  File "/home/harsh/anaconda3/envs/unet_env/lib/python3.8/site-packages/wandb/sdk/lib/gql_request.py", line 59, in execute
    request.raise_for_status()
  File "/home/harsh/anaconda3/envs/unet_env/lib/python3.8/site-packages/requests/models.py", line 1024, in raise_for_status
    raise HTTPError(http_error_msg, response=self)
requests.exceptions.HTTPError: 404 Client Error: Not Found for url: https://api.wandb.ai/graphql

During handling of the above exception, another exception occurred:

Traceback (most recent call last):
  File "/home/harsh/anaconda3/envs/unet_env/lib/python3.8/site-packages/wandb/sdk/internal/sender.py", line 1007, in send_run
    server_run = self._init_run(run, config_value_dict)
  File "/home/harsh/anaconda3/envs/unet_env/lib/python3.8/site-packages/wandb/sdk/internal/sender.py", line 1079, in _init_run
    server_run, inserted, server_messages = self._api.upsert_run(
  File "/home/harsh/anaconda3/envs/unet_env/lib/python3.8/site-packages/wandb/apis/normalize.py", line 73, in wrapper
    raise err
  File "/home/harsh/anaconda3/envs/unet_env/lib/python3.8/site-packages/wandb/apis/normalize.py", line 41, in wrapper
    return func(*args, **kwargs)
  File "/home/harsh/anaconda3/envs/unet_env/lib/python3.8/site-packages/wandb/sdk/internal/internal_api.py", line 2190, in upsert_run
    response = self.gql(
  File "/home/harsh/anaconda3/envs/unet_env/lib/python3.8/site-packages/wandb/sdk/internal/internal_api.py", line 312, in gql
    ret = self._retry_gql(
  File "/home/harsh/anaconda3/envs/unet_env/lib/python3.8/site-packages/wandb/sdk/lib/retry.py", line 147, in __call__
    retry_timedelta_triggered = check_retry_fn(e)
  File "/home/harsh/anaconda3/envs/unet_env/lib/python3.8/site-packages/wandb/util.py", line 968, in check_retry_fn
    return fallback_retry_fn(e)
  File "/home/harsh/anaconda3/envs/unet_env/lib/python3.8/site-packages/wandb/util.py", line 910, in no_retry_auth
    raise CommError(
wandb.errors.CommError: It appears that you do not have permission to access the requested resource. Please reach out to the project owner to grant you access. If you have the correct permissions, verify that there are no issues with your networking setup.(Error 404: Not Found)
2024-06-18 11:55:22,502 DEBUG   HandlerThread:22507 [handler.py:handle_request():158] handle_request: status_report
2024-06-18 11:55:27,503 DEBUG   HandlerThread:22507 [handler.py:handle_request():158] handle_request: status_report
2024-06-18 11:55:32,503 DEBUG   HandlerThread:22507 [handler.py:handle_request():158] handle_request: status_report
2024-06-18 11:55:37,504 DEBUG   HandlerThread:22507 [handler.py:handle_request():158] handle_request: status_report
2024-06-18 11:55:42,505 DEBUG   HandlerThread:22507 [handler.py:handle_request():158] handle_request: status_report
2024-06-18 11:55:47,506 DEBUG   HandlerThread:22507 [handler.py:handle_request():158] handle_request: status_report
2024-06-18 11:55:52,507 DEBUG   HandlerThread:22507 [handler.py:handle_request():158] handle_request: status_report
2024-06-18 11:55:57,508 DEBUG   HandlerThread:22507 [handler.py:handle_request():158] handle_request: status_report
2024-06-18 11:56:02,509 DEBUG   HandlerThread:22507 [handler.py:handle_request():158] handle_request: status_report
2024-06-18 11:56:07,510 DEBUG   HandlerThread:22507 [handler.py:handle_request():158] handle_request: status_report
2024-06-18 11:56:12,511 DEBUG   HandlerThread:22507 [handler.py:handle_request():158] handle_request: status_report
2024-06-18 11:56:17,512 DEBUG   HandlerThread:22507 [handler.py:handle_request():158] handle_request: status_report
2024-06-18 11:56:17,741 DEBUG   HandlerThread:22507 [handler.py:handle_request():158] handle_request: shutdown
2024-06-18 11:56:17,741 INFO    HandlerThread:22507 [handler.py:finish():882] shutting down handler
2024-06-18 11:56:18,512 INFO    SenderThread:22507 [sender.py:finish():1608] shutting down sender
2024-06-18 11:56:18,512 INFO    WriterThread:22507 [datastore.py:close():296] close: /home/harsh/Downloads/PROJECTS/road_detection_unet/wandb/run-20240618_115516-3nfitrn2/run-3nfitrn2.wandb
