2024-06-18 12:13:45,163 INFO    StreamThr :23245 [internal.py:wandb_internal():85] W&B internal server running at pid: 23245, started at: 2024-06-18 12:13:45.163182
2024-06-18 12:13:45,164 DEBUG   HandlerThread:23245 [handler.py:handle_request():158] handle_request: status
2024-06-18 12:13:45,167 INFO    WriterThread:23245 [datastore.py:open_for_write():87] open: /home/harsh/Downloads/PROJECTS/road_detection_unet/wandb/run-20240618_121345-v6qzcudx/run-v6qzcudx.wandb
2024-06-18 12:13:45,167 DEBUG   SenderThread:23245 [sender.py:send():379] send: header
2024-06-18 12:13:45,192 DEBUG   SenderThread:23245 [sender.py:send():379] send: run
2024-06-18 12:13:45,764 ERROR   SenderThread:23245 [internal_api.py:execute():344] 403 response executing GraphQL.
2024-06-18 12:13:45,764 ERROR   SenderThread:23245 [internal_api.py:execute():345] {"errors":[{"message":"permission denied","path":["upsertBucket"],"extensions":{"code":"PERMISSION_ERROR"}}],"data":{"upsertBucket":null}}
2024-06-18 12:13:45,764 ERROR   SenderThread:23245 [sender.py:send_run():1009] It appears that you do not have permission to access the requested resource. Please reach out to the project owner to grant you access. If you have the correct permissions, verify that there are no issues with your networking setup.(Error 403: Forbidden)
Traceback (most recent call last):
  File "/home/harsh/anaconda3/envs/unet_env/lib/python3.8/site-packages/wandb/sdk/lib/retry.py", line 131, in __call__
    result = self._call_fn(*args, **kwargs)
  File "/home/harsh/anaconda3/envs/unet_env/lib/python3.8/site-packages/wandb/sdk/internal/internal_api.py", line 340, in execute
    return self.client.execute(*args, **kwargs)  # type: ignore
  File "/home/harsh/anaconda3/envs/unet_env/lib/python3.8/site-packages/wandb/vendor/gql-0.2.0/wandb_gql/client.py", line 52, in execute
    result = self._get_result(document, *args, **kwargs)
  File "/home/harsh/anaconda3/envs/unet_env/lib/python3.8/site-packages/wandb/vendor/gql-0.2.0/wandb_gql/client.py", line 60, in _get_result
    return self.transport.execute(document, *args, **kwargs)
  File "/home/harsh/anaconda3/envs/unet_env/lib/python3.8/site-packages/wandb/sdk/lib/gql_request.py", line 59, in execute
    request.raise_for_status()
  File "/home/harsh/anaconda3/envs/unet_env/lib/python3.8/site-packages/requests/models.py", line 1024, in raise_for_status
    raise HTTPError(http_error_msg, response=self)
requests.exceptions.HTTPError: 403 Client Error: Forbidden for url: https://api.wandb.ai/graphql

During handling of the above exception, another exception occurred:

Traceback (most recent call last):
  File "/home/harsh/anaconda3/envs/unet_env/lib/python3.8/site-packages/wandb/sdk/internal/sender.py", line 1007, in send_run
    server_run = self._init_run(run, config_value_dict)
  File "/home/harsh/anaconda3/envs/unet_env/lib/python3.8/site-packages/wandb/sdk/internal/sender.py", line 1079, in _init_run
    server_run, inserted, server_messages = self._api.upsert_run(
  File "/home/harsh/anaconda3/envs/unet_env/lib/python3.8/site-packages/wandb/apis/normalize.py", line 73, in wrapper
    raise err
  File "/home/harsh/anaconda3/envs/unet_env/lib/python3.8/site-packages/wandb/apis/normalize.py", line 41, in wrapper
    return func(*args, **kwargs)
  File "/home/harsh/anaconda3/envs/unet_env/lib/python3.8/site-packages/wandb/sdk/internal/internal_api.py", line 2190, in upsert_run
    response = self.gql(
  File "/home/harsh/anaconda3/envs/unet_env/lib/python3.8/site-packages/wandb/sdk/internal/internal_api.py", line 312, in gql
    ret = self._retry_gql(
  File "/home/harsh/anaconda3/envs/unet_env/lib/python3.8/site-packages/wandb/sdk/lib/retry.py", line 147, in __call__
    retry_timedelta_triggered = check_retry_fn(e)
  File "/home/harsh/anaconda3/envs/unet_env/lib/python3.8/site-packages/wandb/util.py", line 968, in check_retry_fn
    return fallback_retry_fn(e)
  File "/home/harsh/anaconda3/envs/unet_env/lib/python3.8/site-packages/wandb/util.py", line 910, in no_retry_auth
    raise CommError(
wandb.errors.CommError: It appears that you do not have permission to access the requested resource. Please reach out to the project owner to grant you access. If you have the correct permissions, verify that there are no issues with your networking setup.(Error 403: Forbidden)
2024-06-18 12:13:50,768 DEBUG   HandlerThread:23245 [handler.py:handle_request():158] handle_request: status_report
2024-06-18 12:13:55,769 DEBUG   HandlerThread:23245 [handler.py:handle_request():158] handle_request: status_report
2024-06-18 12:14:00,770 DEBUG   HandlerThread:23245 [handler.py:handle_request():158] handle_request: status_report
2024-06-18 12:14:05,771 DEBUG   HandlerThread:23245 [handler.py:handle_request():158] handle_request: status_report
2024-06-18 12:14:10,771 DEBUG   HandlerThread:23245 [handler.py:handle_request():158] handle_request: status_report
2024-06-18 12:14:15,772 DEBUG   HandlerThread:23245 [handler.py:handle_request():158] handle_request: status_report
2024-06-18 12:14:20,773 DEBUG   HandlerThread:23245 [handler.py:handle_request():158] handle_request: status_report
2024-06-18 12:14:25,774 DEBUG   HandlerThread:23245 [handler.py:handle_request():158] handle_request: status_report
2024-06-18 12:14:30,774 DEBUG   HandlerThread:23245 [handler.py:handle_request():158] handle_request: status_report
2024-06-18 12:14:35,775 DEBUG   HandlerThread:23245 [handler.py:handle_request():158] handle_request: status_report
2024-06-18 12:14:40,775 DEBUG   HandlerThread:23245 [handler.py:handle_request():158] handle_request: status_report
2024-06-18 12:14:45,776 DEBUG   HandlerThread:23245 [handler.py:handle_request():158] handle_request: status_report
2024-06-18 12:14:50,777 DEBUG   HandlerThread:23245 [handler.py:handle_request():158] handle_request: status_report
2024-06-18 12:14:55,777 DEBUG   HandlerThread:23245 [handler.py:handle_request():158] handle_request: status_report
2024-06-18 12:15:00,778 DEBUG   HandlerThread:23245 [handler.py:handle_request():158] handle_request: status_report
2024-06-18 12:15:05,779 DEBUG   HandlerThread:23245 [handler.py:handle_request():158] handle_request: status_report
2024-06-18 12:15:10,780 DEBUG   HandlerThread:23245 [handler.py:handle_request():158] handle_request: status_report
2024-06-18 12:15:15,781 DEBUG   HandlerThread:23245 [handler.py:handle_request():158] handle_request: status_report
2024-06-18 12:15:20,782 DEBUG   HandlerThread:23245 [handler.py:handle_request():158] handle_request: status_report
2024-06-18 12:15:25,783 DEBUG   HandlerThread:23245 [handler.py:handle_request():158] handle_request: status_report
2024-06-18 12:15:30,783 DEBUG   HandlerThread:23245 [handler.py:handle_request():158] handle_request: status_report
2024-06-18 12:15:35,784 DEBUG   HandlerThread:23245 [handler.py:handle_request():158] handle_request: status_report
2024-06-18 12:15:40,785 DEBUG   HandlerThread:23245 [handler.py:handle_request():158] handle_request: status_report
2024-06-18 12:15:45,785 DEBUG   HandlerThread:23245 [handler.py:handle_request():158] handle_request: status_report
2024-06-18 12:15:50,787 DEBUG   HandlerThread:23245 [handler.py:handle_request():158] handle_request: status_report
2024-06-18 12:15:55,787 DEBUG   HandlerThread:23245 [handler.py:handle_request():158] handle_request: status_report
2024-06-18 12:15:57,136 DEBUG   HandlerThread:23245 [handler.py:handle_request():158] handle_request: shutdown
2024-06-18 12:15:57,136 INFO    HandlerThread:23245 [handler.py:finish():882] shutting down handler
2024-06-18 12:15:57,787 INFO    SenderThread:23245 [sender.py:finish():1608] shutting down sender
2024-06-18 12:15:57,788 INFO    WriterThread:23245 [datastore.py:close():296] close: /home/harsh/Downloads/PROJECTS/road_detection_unet/wandb/run-20240618_121345-v6qzcudx/run-v6qzcudx.wandb
